{"testRequestResultStorage":[{"author":"Client 2","listOfTestDriverResult":[{"listOfTestCaseResults":[{"logs":"\u000a entering into TestDriver1 - > test() method\u000a demo for normal execution\u000a Result :- True","testName":"TestDriver.TestDriver1","testResult":"True"},{"logs":"\u000a entering into TestDriver2 - > test() method\u000a tests how test harness handles throws and catches instances of exception\u000a Result :- False","testName":"TestDriver.TestDriver2","testResult":"False"},{"logs":"\u000aResult :- True","testName":"TestDriver.TestDriver12","testResult":"True"},{"logs":"\u000a entering into TestDriver3 - > test() method\u000a throws instance of Exception but does not catch\u000a Result :- False","testName":"TestDriver.TestDriver3","testResult":"False"},{"logs":"\u000a entering into TestDriver4 - > test() method\u000a how test harness handles divide by zero that is catched in codetotest\u000a Result :- False","testName":"TestDriver.TestDriver4","testResult":"False"}],"testDriverName":"TestDriver1, Version=1.0.0.0, Culture=neutral, PublicKeyToken=null"},{"listOfTestCaseResults":[{"logs":"\u000a entering into TestDriver5 - > test() method\u000a divides by zero but does not try to catch exception\u000a Result :- False","testName":"TestDriver.TestDriver5","testResult":"False"},{"logs":"\u000aResult :- True","testName":"TestDriver.TestDriver11","testResult":"True"},{"logs":"\u000a entering into TestDriver6 - > test() method\u000a calls thread.abort() and tries to catch exception","testName":"TestDriver.TestDriver6","testResult":"False"},{"logs":"\u000a entering into TestDriver7 - > test() method calls thread.abort() but does not try to catch exception","testName":"TestDriver.TestDriver7","testResult":"False"},{"logs":"\u000a entering into TestDriver8 - > test() method\u000a Demonstrating how test harness will handle null pointer exception in test driver that is catched in code to testwith out initializing System.Test.StringBuilder sb, Test driver is calling one of its method sb.Append()\u000aResult :- False","testName":"TestDriver.TestDriver8","testResult":"False"},{"logs":"Result :- True","testName":"TestDriver.TestDriver10","testResult":"True"},{"logs":"\u000a entering into TestDriver9 - > test() method\u000a Demonstrating how test harness will handle null pointer exception in test driverthat doesn't catch itwith out initializing System.Test.StringBuilder sb,  Test driver is calling one of its method sb.Append()","testName":"TestDriver.TestDriver9","testResult":"False"}],"testDriverName":"TestDriver2, Version=1.0.0.0, Culture=neutral, PublicKeyToken=null"}],"testRequestName":"Client 2131242448645065661","timeStamp":"2016-11-21 18:34:24"},{"author":"Pradeep","listOfTestDriverResult":[{"listOfTestCaseResults":[{"logs":"\u000a entering into TestDriver1 - > test() method\u000a demo for normal execution\u000a Result :- True","testName":"TestDriver.TestDriver1","testResult":"True"},{"logs":"\u000a entering into TestDriver2 - > test() method\u000a tests how test harness handles throws and catches instances of exception\u000a Result :- False","testName":"TestDriver.TestDriver2","testResult":"False"},{"logs":"\u000aResult :- True","testName":"TestDriver.TestDriver12","testResult":"True"},{"logs":"\u000a entering into TestDriver3 - > test() method\u000a throws instance of Exception but does not catch\u000a Result :- False","testName":"TestDriver.TestDriver3","testResult":"False"},{"logs":"\u000a entering into TestDriver4 - > test() method\u000a how test harness handles divide by zero that is catched in codetotest\u000a Result :- False","testName":"TestDriver.TestDriver4","testResult":"False"}],"testDriverName":"TestDriver1, Version=1.0.0.0, Culture=neutral, PublicKeyToken=null"},{"listOfTestCaseResults":[{"logs":"\u000a entering into TestDriver5 - > test() method\u000a divides by zero but does not try to catch exception\u000a Result :- False","testName":"TestDriver.TestDriver5","testResult":"False"},{"logs":"\u000aResult :- True","testName":"TestDriver.TestDriver11","testResult":"True"},{"logs":"\u000a entering into TestDriver6 - > test() method\u000a calls thread.abort() and tries to catch exception","testName":"TestDriver.TestDriver6","testResult":"False"},{"logs":"\u000a entering into TestDriver7 - > test() method calls thread.abort() but does not try to catch exception","testName":"TestDriver.TestDriver7","testResult":"False"},{"logs":"\u000a entering into TestDriver8 - > test() method\u000a Demonstrating how test harness will handle null pointer exception in test driver that is catched in code to testwith out initializing System.Test.StringBuilder sb, Test driver is calling one of its method sb.Append()\u000aResult :- False","testName":"TestDriver.TestDriver8","testResult":"False"},{"logs":"Result :- True","testName":"TestDriver.TestDriver10","testResult":"True"},{"logs":"\u000a entering into TestDriver9 - > test() method\u000a Demonstrating how test harness will handle null pointer exception in test driverthat doesn't catch itwith out initializing System.Test.StringBuilder sb,  Test driver is calling one of its method sb.Append()","testName":"TestDriver.TestDriver9","testResult":"False"}],"testDriverName":"TestDriver2, Version=1.0.0.0, Culture=neutral, PublicKeyToken=null"}],"testRequestName":"Pradeep131242448738952380","timeStamp":"2016-11-21 18:34:33"},{"author":"Client 2","listOfTestDriverResult":[{"listOfTestCaseResults":[{"logs":"\u000a entering into TestDriver1 - > test() method\u000a demo for normal execution\u000a Result :- True","testName":"TestDriver.TestDriver1","testResult":"True"},{"logs":"\u000a entering into TestDriver2 - > test() method\u000a tests how test harness handles throws and catches instances of exception\u000a Result :- False","testName":"TestDriver.TestDriver2","testResult":"False"},{"logs":"\u000aResult :- True","testName":"TestDriver.TestDriver12","testResult":"True"},{"logs":"\u000a entering into TestDriver3 - > test() method\u000a throws instance of Exception but does not catch\u000a Result :- False","testName":"TestDriver.TestDriver3","testResult":"False"},{"logs":"\u000a entering into TestDriver4 - > test() method\u000a how test harness handles divide by zero that is catched in codetotest\u000a Result :- False","testName":"TestDriver.TestDriver4","testResult":"False"}],"testDriverName":"TestDriver1, Version=1.0.0.0, Culture=neutral, PublicKeyToken=null"},{"listOfTestCaseResults":[{"logs":"\u000a entering into TestDriver5 - > test() method\u000a divides by zero but does not try to catch exception\u000a Result :- False","testName":"TestDriver.TestDriver5","testResult":"False"},{"logs":"\u000aResult :- True","testName":"TestDriver.TestDriver11","testResult":"True"},{"logs":"\u000a entering into TestDriver6 - > test() method\u000a calls thread.abort() and tries to catch exception","testName":"TestDriver.TestDriver6","testResult":"False"},{"logs":"\u000a entering into TestDriver7 - > test() method calls thread.abort() but does not try to catch exception","testName":"TestDriver.TestDriver7","testResult":"False"},{"logs":"\u000a entering into TestDriver8 - > test() method\u000a Demonstrating how test harness will handle null pointer exception in test driver that is catched in code to testwith out initializing System.Test.StringBuilder sb, Test driver is calling one of its method sb.Append()\u000aResult :- False","testName":"TestDriver.TestDriver8","testResult":"False"},{"logs":"Result :- True","testName":"TestDriver.TestDriver10","testResult":"True"},{"logs":"\u000a entering into TestDriver9 - > test() method\u000a Demonstrating how test harness will handle null pointer exception in test driverthat doesn't catch itwith out initializing System.Test.StringBuilder sb,  Test driver is calling one of its method sb.Append()","testName":"TestDriver.TestDriver9","testResult":"False"}],"testDriverName":"TestDriver2, Version=1.0.0.0, Culture=neutral, PublicKeyToken=null"}],"testRequestName":"Client 2131242450720313952","timeStamp":"2016-11-21 18:37:52"},{"author":"Pradeep","listOfTestDriverResult":[{"listOfTestCaseResults":[{"logs":"\u000a entering into TestDriver1 - > test() method\u000a demo for normal execution\u000a Result :- True","testName":"TestDriver.TestDriver1","testResult":"True"},{"logs":"\u000a entering into TestDriver2 - > test() method\u000a tests how test harness handles throws and catches instances of exception\u000a Result :- False","testName":"TestDriver.TestDriver2","testResult":"False"},{"logs":"\u000aResult :- True","testName":"TestDriver.TestDriver12","testResult":"True"},{"logs":"\u000a entering into TestDriver3 - > test() method\u000a throws instance of Exception but does not catch\u000a Result :- False","testName":"TestDriver.TestDriver3","testResult":"False"},{"logs":"\u000a entering into TestDriver4 - > test() method\u000a how test harness handles divide by zero that is catched in codetotest\u000a Result :- False","testName":"TestDriver.TestDriver4","testResult":"False"}],"testDriverName":"TestDriver1, Version=1.0.0.0, Culture=neutral, PublicKeyToken=null"},{"listOfTestCaseResults":[{"logs":"\u000a entering into TestDriver5 - > test() method\u000a divides by zero but does not try to catch exception\u000a Result :- False","testName":"TestDriver.TestDriver5","testResult":"False"},{"logs":"\u000aResult :- True","testName":"TestDriver.TestDriver11","testResult":"True"},{"logs":"\u000a entering into TestDriver6 - > test() method\u000a calls thread.abort() and tries to catch exception","testName":"TestDriver.TestDriver6","testResult":"False"},{"logs":"\u000a entering into TestDriver7 - > test() method calls thread.abort() but does not try to catch exception","testName":"TestDriver.TestDriver7","testResult":"False"},{"logs":"\u000a entering into TestDriver8 - > test() method\u000a Demonstrating how test harness will handle null pointer exception in test driver that is catched in code to testwith out initializing System.Test.StringBuilder sb, Test driver is calling one of its method sb.Append()\u000aResult :- False","testName":"TestDriver.TestDriver8","testResult":"False"},{"logs":"Result :- True","testName":"TestDriver.TestDriver10","testResult":"True"},{"logs":"\u000a entering into TestDriver9 - > test() method\u000a Demonstrating how test harness will handle null pointer exception in test driverthat doesn't catch itwith out initializing System.Test.StringBuilder sb,  Test driver is calling one of its method sb.Append()","testName":"TestDriver.TestDriver9","testResult":"False"}],"testDriverName":"TestDriver2, Version=1.0.0.0, Culture=neutral, PublicKeyToken=null"}],"testRequestName":"Pradeep131242451307134508","timeStamp":"2016-11-21 18:38:50"},{"author":"Client 2","listOfTestDriverResult":[{"listOfTestCaseResults":[{"logs":"\u000a entering into TestDriver1 - > test() method\u000a demo for normal execution\u000a Result :- True","testName":"TestDriver.TestDriver1","testResult":"True"},{"logs":"\u000a entering into TestDriver2 - > test() method\u000a tests how test harness handles throws and catches instances of exception\u000a Result :- False","testName":"TestDriver.TestDriver2","testResult":"False"},{"logs":"\u000aResult :- True","testName":"TestDriver.TestDriver12","testResult":"True"},{"logs":"\u000a entering into TestDriver3 - > test() method\u000a throws instance of Exception but does not catch\u000a Result :- False","testName":"TestDriver.TestDriver3","testResult":"False"},{"logs":"\u000a entering into TestDriver4 - > test() method\u000a how test harness handles divide by zero that is catched in codetotest\u000a Result :- False","testName":"TestDriver.TestDriver4","testResult":"False"}],"testDriverName":"TestDriver1, Version=1.0.0.0, Culture=neutral, PublicKeyToken=null"},{"listOfTestCaseResults":[{"logs":"\u000a entering into TestDriver5 - > test() method\u000a divides by zero but does not try to catch exception\u000a Result :- False","testName":"TestDriver.TestDriver5","testResult":"False"},{"logs":"\u000aResult :- True","testName":"TestDriver.TestDriver11","testResult":"True"},{"logs":"\u000a entering into TestDriver6 - > test() method\u000a calls thread.abort() and tries to catch exception","testName":"TestDriver.TestDriver6","testResult":"False"},{"logs":"\u000a entering into TestDriver7 - > test() method calls thread.abort() but does not try to catch exception","testName":"TestDriver.TestDriver7","testResult":"False"},{"logs":"\u000a entering into TestDriver8 - > test() method\u000a Demonstrating how test harness will handle null pointer exception in test driver that is catched in code to testwith out initializing System.Test.StringBuilder sb, Test driver is calling one of its method sb.Append()\u000aResult :- False","testName":"TestDriver.TestDriver8","testResult":"False"},{"logs":"Result :- True","testName":"TestDriver.TestDriver10","testResult":"True"},{"logs":"\u000a entering into TestDriver9 - > test() method\u000a Demonstrating how test harness will handle null pointer exception in test driverthat doesn't catch itwith out initializing System.Test.StringBuilder sb,  Test driver is calling one of its method sb.Append()","testName":"TestDriver.TestDriver9","testResult":"False"}],"testDriverName":"TestDriver2, Version=1.0.0.0, Culture=neutral, PublicKeyToken=null"}],"testRequestName":"Client 2131251157370878043","timeStamp":"2016-12-01 20:28:57"},{"author":"Pavan","listOfTestDriverResult":[{"listOfTestCaseResults":[{"logs":"\u000a entering into TestDriver1 - > test() method\u000a demo for normal execution\u000a Result :- True","testName":"TestDriver.TestDriver1","testResult":"True"},{"logs":"\u000a entering into TestDriver2 - > test() method\u000a tests how test harness handles throws and catches instances of exception\u000a Result :- False","testName":"TestDriver.TestDriver2","testResult":"False"},{"logs":"\u000aResult :- True","testName":"TestDriver.TestDriver12","testResult":"True"},{"logs":"\u000a entering into TestDriver3 - > test() method\u000a throws instance of Exception but does not catch\u000a Result :- False","testName":"TestDriver.TestDriver3","testResult":"False"},{"logs":"\u000a entering into TestDriver4 - > test() method\u000a how test harness handles divide by zero that is catched in codetotest\u000a Result :- False","testName":"TestDriver.TestDriver4","testResult":"False"}],"testDriverName":"TestDriver1, Version=1.0.0.0, Culture=neutral, PublicKeyToken=null"},{"listOfTestCaseResults":[{"logs":"\u000a entering into TestDriver5 - > test() method\u000a divides by zero but does not try to catch exception\u000a Result :- False","testName":"TestDriver.TestDriver5","testResult":"False"},{"logs":"\u000aResult :- True","testName":"TestDriver.TestDriver11","testResult":"True"},{"logs":"\u000a entering into TestDriver6 - > test() method\u000a calls thread.abort() and tries to catch exception","testName":"TestDriver.TestDriver6","testResult":"False"},{"logs":"\u000a entering into TestDriver7 - > test() method calls thread.abort() but does not try to catch exception","testName":"TestDriver.TestDriver7","testResult":"False"},{"logs":"\u000a entering into TestDriver8 - > test() method\u000a Demonstrating how test harness will handle null pointer exception in test driver that is catched in code to testwith out initializing System.Test.StringBuilder sb, Test driver is calling one of its method sb.Append()\u000aResult :- False","testName":"TestDriver.TestDriver8","testResult":"False"},{"logs":"Result :- True","testName":"TestDriver.TestDriver10","testResult":"True"},{"logs":"\u000a entering into TestDriver9 - > test() method\u000a Demonstrating how test harness will handle null pointer exception in test driverthat doesn't catch itwith out initializing System.Test.StringBuilder sb,  Test driver is calling one of its method sb.Append()","testName":"TestDriver.TestDriver9","testResult":"False"}],"testDriverName":"TestDriver2, Version=1.0.0.0, Culture=neutral, PublicKeyToken=null"}],"testRequestName":"Pavan131251157709978683","timeStamp":"2016-12-01 20:29:30"},{"author":"Client 2","listOfTestDriverResult":[{"listOfTestCaseResults":[{"logs":"\u000a entering into TestDriver1 - > test() method\u000a demo for normal execution\u000a Result :- True","testName":"TestDriver.TestDriver1","testResult":"True"},{"logs":"\u000a entering into TestDriver2 - > test() method\u000a tests how test harness handles throws and catches instances of exception\u000a Result :- False","testName":"TestDriver.TestDriver2","testResult":"False"},{"logs":"\u000aResult :- True","testName":"TestDriver.TestDriver12","testResult":"True"},{"logs":"\u000a entering into TestDriver3 - > test() method\u000a throws instance of Exception but does not catch\u000a Result :- False","testName":"TestDriver.TestDriver3","testResult":"False"},{"logs":"\u000a entering into TestDriver4 - > test() method\u000a how test harness handles divide by zero that is catched in codetotest\u000a Result :- False","testName":"TestDriver.TestDriver4","testResult":"False"}],"testDriverName":"TestDriver1, Version=1.0.0.0, Culture=neutral, PublicKeyToken=null"},{"listOfTestCaseResults":[{"logs":"\u000a entering into TestDriver5 - > test() method\u000a divides by zero but does not try to catch exception\u000a Result :- False","testName":"TestDriver.TestDriver5","testResult":"False"},{"logs":"\u000aResult :- True","testName":"TestDriver.TestDriver11","testResult":"True"},{"logs":"\u000a entering into TestDriver6 - > test() method\u000a calls thread.abort() and tries to catch exception","testName":"TestDriver.TestDriver6","testResult":"False"},{"logs":"\u000a entering into TestDriver7 - > test() method calls thread.abort() but does not try to catch exception","testName":"TestDriver.TestDriver7","testResult":"False"},{"logs":"\u000a entering into TestDriver8 - > test() method\u000a Demonstrating how test harness will handle null pointer exception in test driver that is catched in code to testwith out initializing System.Test.StringBuilder sb, Test driver is calling one of its method sb.Append()\u000aResult :- False","testName":"TestDriver.TestDriver8","testResult":"False"},{"logs":"Result :- True","testName":"TestDriver.TestDriver10","testResult":"True"},{"logs":"\u000a entering into TestDriver9 - > test() method\u000a Demonstrating how test harness will handle null pointer exception in test driverthat doesn't catch itwith out initializing System.Test.StringBuilder sb,  Test driver is calling one of its method sb.Append()","testName":"TestDriver.TestDriver9","testResult":"False"}],"testDriverName":"TestDriver2, Version=1.0.0.0, Culture=neutral, PublicKeyToken=null"}],"testRequestName":"Client 2131251168111641378","timeStamp":"2016-12-01 20:46:51"},{"author":"Pavan","listOfTestDriverResult":[{"listOfTestCaseResults":[{"logs":"\u000a entering into TestDriver1 - > test() method\u000a demo for normal execution\u000a Result :- True","testName":"TestDriver.TestDriver1","testResult":"True"},{"logs":"\u000a entering into TestDriver2 - > test() method\u000a tests how test harness handles throws and catches instances of exception\u000a Result :- False","testName":"TestDriver.TestDriver2","testResult":"False"},{"logs":"\u000aResult :- True","testName":"TestDriver.TestDriver12","testResult":"True"},{"logs":"\u000a entering into TestDriver3 - > test() method\u000a throws instance of Exception but does not catch\u000a Result :- False","testName":"TestDriver.TestDriver3","testResult":"False"},{"logs":"\u000a entering into TestDriver4 - > test() method\u000a how test harness handles divide by zero that is catched in codetotest\u000a Result :- False","testName":"TestDriver.TestDriver4","testResult":"False"}],"testDriverName":"TestDriver1, Version=1.0.0.0, Culture=neutral, PublicKeyToken=null"}],"testRequestName":"Pavan131251170589248936","timeStamp":"2016-12-01 20:50:58"},{"author":"Client 2","listOfTestDriverResult":[{"listOfTestCaseResults":[{"logs":"\u000a entering into TestDriver1 - > test() method\u000a demo for normal execution\u000a Result :- True","testName":"TestDriver.TestDriver1","testResult":"True"},{"logs":"\u000a entering into TestDriver2 - > test() method\u000a tests how test harness handles throws and catches instances of exception\u000a Result :- False","testName":"TestDriver.TestDriver2","testResult":"False"},{"logs":"\u000aResult :- True","testName":"TestDriver.TestDriver12","testResult":"True"},{"logs":"\u000a entering into TestDriver3 - > test() method\u000a throws instance of Exception but does not catch\u000a Result :- False","testName":"TestDriver.TestDriver3","testResult":"False"},{"logs":"\u000a entering into TestDriver4 - > test() method\u000a how test harness handles divide by zero that is catched in codetotest\u000a Result :- False","testName":"TestDriver.TestDriver4","testResult":"False"}],"testDriverName":"TestDriver1, Version=1.0.0.0, Culture=neutral, PublicKeyToken=null"},{"listOfTestCaseResults":[{"logs":"\u000a entering into TestDriver5 - > test() method\u000a divides by zero but does not try to catch exception\u000a Result :- False","testName":"TestDriver.TestDriver5","testResult":"False"},{"logs":"\u000aResult :- True","testName":"TestDriver.TestDriver11","testResult":"True"},{"logs":"\u000a entering into TestDriver6 - > test() method\u000a calls thread.abort() and tries to catch exception","testName":"TestDriver.TestDriver6","testResult":"False"},{"logs":"\u000a entering into TestDriver7 - > test() method calls thread.abort() but does not try to catch exception","testName":"TestDriver.TestDriver7","testResult":"False"},{"logs":"\u000a entering into TestDriver8 - > test() method\u000a Demonstrating how test harness will handle null pointer exception in test driver that is catched in code to testwith out initializing System.Test.StringBuilder sb, Test driver is calling one of its method sb.Append()\u000aResult :- False","testName":"TestDriver.TestDriver8","testResult":"False"},{"logs":"Result :- True","testName":"TestDriver.TestDriver10","testResult":"True"},{"logs":"\u000a entering into TestDriver9 - > test() method\u000a Demonstrating how test harness will handle null pointer exception in test driverthat doesn't catch itwith out initializing System.Test.StringBuilder sb,  Test driver is calling one of its method sb.Append()","testName":"TestDriver.TestDriver9","testResult":"False"}],"testDriverName":"TestDriver2, Version=1.0.0.0, Culture=neutral, PublicKeyToken=null"}],"testRequestName":"Client 2131251180804057421","timeStamp":"2016-12-01 21:08:00"},{"author":"pavan","listOfTestDriverResult":[{"listOfTestCaseResults":[{"logs":"\u000a entering into TestDriver1 - > test() method\u000a demo for normal execution\u000a Result :- True","testName":"TestDriver.TestDriver1","testResult":"True"},{"logs":"\u000a entering into TestDriver2 - > test() method\u000a tests how test harness handles throws and catches instances of exception\u000a Result :- False","testName":"TestDriver.TestDriver2","testResult":"False"},{"logs":"\u000aResult :- True","testName":"TestDriver.TestDriver12","testResult":"True"},{"logs":"\u000a entering into TestDriver3 - > test() method\u000a throws instance of Exception but does not catch\u000a Result :- False","testName":"TestDriver.TestDriver3","testResult":"False"},{"logs":"\u000a entering into TestDriver4 - > test() method\u000a how test harness handles divide by zero that is catched in codetotest\u000a Result :- False","testName":"TestDriver.TestDriver4","testResult":"False"}],"testDriverName":"TestDriver1, Version=1.0.0.0, Culture=neutral, PublicKeyToken=null"},{"listOfTestCaseResults":[{"logs":"\u000a entering into TestDriver5 - > test() method\u000a divides by zero but does not try to catch exception\u000a Result :- False","testName":"TestDriver.TestDriver5","testResult":"False"},{"logs":"\u000aResult :- True","testName":"TestDriver.TestDriver11","testResult":"True"},{"logs":"\u000a entering into TestDriver6 - > test() method\u000a calls thread.abort() and tries to catch exception","testName":"TestDriver.TestDriver6","testResult":"False"},{"logs":"\u000a entering into TestDriver7 - > test() method calls thread.abort() but does not try to catch exception","testName":"TestDriver.TestDriver7","testResult":"False"},{"logs":"\u000a entering into TestDriver8 - > test() method\u000a Demonstrating how test harness will handle null pointer exception in test driver that is catched in code to testwith out initializing System.Test.StringBuilder sb, Test driver is calling one of its method sb.Append()\u000aResult :- False","testName":"TestDriver.TestDriver8","testResult":"False"},{"logs":"Result :- True","testName":"TestDriver.TestDriver10","testResult":"True"},{"logs":"\u000a entering into TestDriver9 - > test() method\u000a Demonstrating how test harness will handle null pointer exception in test driverthat doesn't catch itwith out initializing System.Test.StringBuilder sb,  Test driver is calling one of its method sb.Append()","testName":"TestDriver.TestDriver9","testResult":"False"}],"testDriverName":"TestDriver2, Version=1.0.0.0, Culture=neutral, PublicKeyToken=null"}],"testRequestName":"pavan131251185430562204","timeStamp":"2016-12-01 21:15:43"},{"author":"Client 2","listOfTestDriverResult":[{"listOfTestCaseResults":[{"logs":"\u000a entering into TestDriver1 - > test() method\u000a demo for normal execution\u000a Result :- True","testName":"TestDriver.TestDriver1","testResult":"True"},{"logs":"\u000a entering into TestDriver2 - > test() method\u000a tests how test harness handles throws and catches instances of exception\u000a Result :- False","testName":"TestDriver.TestDriver2","testResult":"False"},{"logs":"\u000aResult :- True","testName":"TestDriver.TestDriver12","testResult":"True"},{"logs":"\u000a entering into TestDriver3 - > test() method\u000a throws instance of Exception but does not catch\u000a Result :- False","testName":"TestDriver.TestDriver3","testResult":"False"},{"logs":"\u000a entering into TestDriver4 - > test() method\u000a how test harness handles divide by zero that is catched in codetotest\u000a Result :- False","testName":"TestDriver.TestDriver4","testResult":"False"}],"testDriverName":"TestDriver1, Version=1.0.0.0, Culture=neutral, PublicKeyToken=null"},{"listOfTestCaseResults":[{"logs":"\u000a entering into TestDriver5 - > test() method\u000a divides by zero but does not try to catch exception\u000a Result :- False","testName":"TestDriver.TestDriver5","testResult":"False"},{"logs":"\u000aResult :- True","testName":"TestDriver.TestDriver11","testResult":"True"},{"logs":"\u000a entering into TestDriver6 - > test() method\u000a calls thread.abort() and tries to catch exception","testName":"TestDriver.TestDriver6","testResult":"False"},{"logs":"\u000a entering into TestDriver7 - > test() method calls thread.abort() but does not try to catch exception","testName":"TestDriver.TestDriver7","testResult":"False"},{"logs":"\u000a entering into TestDriver8 - > test() method\u000a Demonstrating how test harness will handle null pointer exception in test driver that is catched in code to testwith out initializing System.Test.StringBuilder sb, Test driver is calling one of its method sb.Append()\u000aResult :- False","testName":"TestDriver.TestDriver8","testResult":"False"},{"logs":"Result :- True","testName":"TestDriver.TestDriver10","testResult":"True"},{"logs":"\u000a entering into TestDriver9 - > test() method\u000a Demonstrating how test harness will handle null pointer exception in test driverthat doesn't catch itwith out initializing System.Test.StringBuilder sb,  Test driver is calling one of its method sb.Append()","testName":"TestDriver.TestDriver9","testResult":"False"}],"testDriverName":"TestDriver2, Version=1.0.0.0, Culture=neutral, PublicKeyToken=null"}],"testRequestName":"Client 2131251218558280804","timeStamp":"2016-12-01 22:10:55"},{"author":"Client 2","listOfTestDriverResult":[{"listOfTestCaseResults":[{"logs":"\u000a entering into TestDriver1 - > test() method\u000a demo for normal execution\u000a Result :- True","testName":"TestDriver.TestDriver1","testResult":"True"},{"logs":"\u000a entering into TestDriver2 - > test() method\u000a tests how test harness handles throws and catches instances of exception\u000a Result :- False","testName":"TestDriver.TestDriver2","testResult":"False"},{"logs":"\u000aResult :- True","testName":"TestDriver.TestDriver12","testResult":"True"},{"logs":"\u000a entering into TestDriver3 - > test() method\u000a throws instance of Exception but does not catch\u000a Result :- False","testName":"TestDriver.TestDriver3","testResult":"False"},{"logs":"\u000a entering into TestDriver4 - > test() method\u000a how test harness handles divide by zero that is catched in codetotest\u000a Result :- False","testName":"TestDriver.TestDriver4","testResult":"False"}],"testDriverName":"TestDriver1, Version=1.0.0.0, Culture=neutral, PublicKeyToken=null"},{"listOfTestCaseResults":[{"logs":"\u000a entering into TestDriver5 - > test() method\u000a divides by zero but does not try to catch exception\u000a Result :- False","testName":"TestDriver.TestDriver5","testResult":"False"},{"logs":"\u000aResult :- True","testName":"TestDriver.TestDriver11","testResult":"True"},{"logs":"\u000a entering into TestDriver6 - > test() method\u000a calls thread.abort() and tries to catch exception","testName":"TestDriver.TestDriver6","testResult":"False"},{"logs":"\u000a entering into TestDriver7 - > test() method calls thread.abort() but does not try to catch exception","testName":"TestDriver.TestDriver7","testResult":"False"},{"logs":"\u000a entering into TestDriver8 - > test() method\u000a Demonstrating how test harness will handle null pointer exception in test driver that is catched in code to testwith out initializing System.Test.StringBuilder sb, Test driver is calling one of its method sb.Append()\u000aResult :- False","testName":"TestDriver.TestDriver8","testResult":"False"},{"logs":"Result :- True","testName":"TestDriver.TestDriver10","testResult":"True"},{"logs":"\u000a entering into TestDriver9 - > test() method\u000a Demonstrating how test harness will handle null pointer exception in test driverthat doesn't catch itwith out initializing System.Test.StringBuilder sb,  Test driver is calling one of its method sb.Append()","testName":"TestDriver.TestDriver9","testResult":"False"}],"testDriverName":"TestDriver2, Version=1.0.0.0, Culture=neutral, PublicKeyToken=null"}],"testRequestName":"Client 2131282258716824424","timeStamp":"2017-01-06 20:24:31"},{"author":"Santhosh","listOfTestDriverResult":[{"listOfTestCaseResults":[{"logs":"\u000a entering into TestDriver1 - > test() method\u000a demo for normal execution\u000a Result :- True","testName":"TestDriver.TestDriver1","testResult":"True"},{"logs":"\u000a entering into TestDriver2 - > test() method\u000a tests how test harness handles throws and catches instances of exception\u000a Result :- False","testName":"TestDriver.TestDriver2","testResult":"False"},{"logs":"\u000aResult :- True","testName":"TestDriver.TestDriver12","testResult":"True"},{"logs":"\u000a entering into TestDriver3 - > test() method\u000a throws instance of Exception but does not catch\u000a Result :- False","testName":"TestDriver.TestDriver3","testResult":"False"},{"logs":"\u000a entering into TestDriver4 - > test() method\u000a how test harness handles divide by zero that is catched in codetotest\u000a Result :- False","testName":"TestDriver.TestDriver4","testResult":"False"}],"testDriverName":"TestDriver1, Version=1.0.0.0, Culture=neutral, PublicKeyToken=null"},{"listOfTestCaseResults":[{"logs":"\u000a entering into TestDriver5 - > test() method\u000a divides by zero but does not try to catch exception\u000a Result :- False","testName":"TestDriver.TestDriver5","testResult":"False"},{"logs":"\u000aResult :- True","testName":"TestDriver.TestDriver11","testResult":"True"},{"logs":"\u000a entering into TestDriver6 - > test() method\u000a calls thread.abort() and tries to catch exception","testName":"TestDriver.TestDriver6","testResult":"False"},{"logs":"\u000a entering into TestDriver7 - > test() method calls thread.abort() but does not try to catch exception","testName":"TestDriver.TestDriver7","testResult":"False"},{"logs":"\u000a entering into TestDriver8 - > test() method\u000a Demonstrating how test harness will handle null pointer exception in test driver that is catched in code to testwith out initializing System.Test.StringBuilder sb, Test driver is calling one of its method sb.Append()\u000aResult :- False","testName":"TestDriver.TestDriver8","testResult":"False"},{"logs":"Result :- True","testName":"TestDriver.TestDriver10","testResult":"True"},{"logs":"\u000a entering into TestDriver9 - > test() method\u000a Demonstrating how test harness will handle null pointer exception in test driverthat doesn't catch itwith out initializing System.Test.StringBuilder sb,  Test driver is calling one of its method sb.Append()","testName":"TestDriver.TestDriver9","testResult":"False"}],"testDriverName":"TestDriver2, Version=1.0.0.0, Culture=neutral, PublicKeyToken=null"}],"testRequestName":"Santhosh131282258826939308","timeStamp":"2017-01-06 20:24:42"}]}